Workbook
Name Slicer_GENDER_LABEL: #N/A

Sheet Demographic
A1: SEQN | B1: GENDER | C1: AGE | D1: GENDER_LABEL | E1: =MEDIAN(C:C) -> 31 | F1: AGE_CLEANED | G1: BMI_CLEANED | H1: CHOLESTEROL_CLEANED
A2: 93703 | B2: 2 | C2: 2 | D2: =IF(B2=1,"Male",IF(B2=2,"Female","Unknown")) -> Female | F2: =IF(C2<1, $E$1, C2) -> 2 | G2: =_xlfn.XLOOKUP(A2, BMI!A:A, BMI!E:E, "Missing", 0) -> 17.5 | H2: =_xlfn.XLOOKUP(A2, Cholesterol!A:A, Cholesterol!E:E, "Missing", 0) -> Missing
A3: 93704 | B3: 1 | C3: 2 | D3: =IF(B3=1,"Male",IF(B3=2,"Female","Unknown")) -> Male | F3: =IF(C3<1, $E$1, C3) -> 2 | G3: =_xlfn.XLOOKUP(A3, BMI!A:A, BMI!E:E, "Missing", 0) -> 15.7 | H3: =_xlfn.XLOOKUP(A3, Cholesterol!A:A, Cholesterol!E:E, "Missing", 0) -> Missing
A4: 93705 | B4: 2 | C4: 66 | D4: =IF(B4=1,"Male",IF(B4=2,"Female","Unknown")) -> Female | F4: =IF(C4<1, $E$1, C4) -> 66 | G4: =_xlfn.XLOOKUP(A4, BMI!A:A, BMI!E:E, "Missing", 0) -> 31.7 | H4: =_xlfn.XLOOKUP(A4, Cholesterol!A:A, Cholesterol!E:E, "Missing", 0) -> 157
A5: 93706 | B5: 1 | C5: 18 | D5: =IF(B5=1,"Male",IF(B5=2,"Female","Unknown")) -> Male | F5: =IF(C5<1, $E$1, C5) -> 18 | G5: =_xlfn.XLOOKUP(A5, BMI!A:A, BMI!E:E, "Missing", 0) -> 21.5 | H5: =_xlfn.XLOOKUP(A5, Cholesterol!A:A, Cholesterol!E:E, "Missing", 0) -> 148
A6: 93707 | B6: 1 | C6: 13 | D6: =IF(B6=1,"Male",IF(B6=2,"Female","Unknown")) -> Male | F6: =IF(C6<1, $E$1, C6) -> 13 | G6: =_xlfn.XLOOKUP(A6, BMI!A:A, BMI!E:E, "Missing", 0) -> 18.1 | H6: =_xlfn.XLOOKUP(A6, Cholesterol!A:A, Cholesterol!E:E, "Missing", 0) -> 189
A7: 93708 | B7: 2 | C7: 66 | D7: =IF(B7=1,"Male",IF(B7=2,"Female","Unknown")) -> Female | F7: =IF(C7<1, $E$1, C7) -> 66 | G7: =_xlfn.XLOOKUP(A7, BMI!A:A, BMI!E:E, "Missing", 0) -> 23.7 | H7: =_xlfn.XLOOKUP(A7, Cholesterol!A:A, Cholesterol!E:E, "Missing", 0) -> 209
A8: 93709 | B8: 2 | C8: 75 | D8: =IF(B8=1,"Male",IF(B8=2,"Female","Unknown")) -> Female | F8: =IF(C8<1, $E$1, C8) -> 75 | G8: =_xlfn.XLOOKUP(A8, BMI!A:A, BMI!E:E, "Missing", 0) -> 38.9 | H8: =_xlfn.XLOOKUP(A8, Cholesterol!A:A, Cholesterol!E:E, "Missing", 0) -> 176
A9: 93710 | B9: 2 | C9: 5.3976053e-79 | D9: =IF(B9=1,"Male",IF(B9=2,"Female","Unknown")) -> Female | F9: =IF(C9<1, $E$1, C9) -> 31 | G9: =_xlfn.XLOOKUP(A9, BMI!A:A, BMI!E:E, "Missing", 0) -> 25.8 | H9: =_xlfn.XLOOKUP(A9, Cholesterol!A:A, Cholesterol!E:E, "Missing", 0) -> Missing
A10: 93711 | B10: 1 | C10: 56 | D10: =IF(B10=1,"Male",IF(B10=2,"Female","Unknown")) -> Male | F10: =IF(C10<1, $E$1, C10) -> 56 | G10: =_xlfn.XLOOKUP(A10, BMI!A:A, BMI!E:E, "Missing", 0) -> 21.3 | H10: =_xlfn.XLOOKUP(A10, Cholesterol!A:A, Cholesterol!E:E, "Missing", 0) -> 238
A11: 93712 | B11: 1 | C11: 18 | D11: =IF(B11=1,"Male",IF(B11=2,"Female","Unknown")) -> Male | F11: =IF(C11<1, $E$1, C11) -> 18 | G11: =_xlfn.XLOOKUP(A11, BMI!A:A, BMI!E:E, "Missing", 0) -> 19.7 | H11: =_xlfn.XLOOKUP(A11, Cholesterol!A:A, Cholesterol!E:E, "Missing", 0) -> 182
A12: 93713 | B12: 1 | C12: 67 | D12: =IF(B12=1,"Male",IF(B12=2,"Female","Unknown")) -> Male | F12: =IF(C12<1, $E$1, C12) -> 67 | G12: =_xlfn.XLOOKUP(A12, BMI!A:A, BMI!E:E, "Missing", 0) -> 23.5 | H12: =_xlfn.XLOOKUP(A12, Cholesterol!A:A, Cholesterol!E:E, "Missing", 0) -> 184
A13: 93714 | B13: 2 | C13: 54 | D13: =IF(B13=1,"Male",IF(B13=2,"Female","Unknown")) -> Female | F13: =IF(C13<1, $E$1, C13) -> 54 | G13: =_xlfn.XLOOKUP(A13, BMI!A:A, BMI!E:E, "Missing", 0) -> 39.9 | H13: =_xlfn.XLOOKUP(A13, Cholesterol!A:A, Cholesterol!E:E, "Missing", 0) -> 230
... A9255: 102956 | B9255: 1 | C9255: 38 | D9255: =IF(B9255=1,"Male",IF(B9255=2,"Female","Unknown")) -> Male | F9255: =IF(C9255<1, $E$1, C9255) -> 38 | G9255: =_xlfn.XLOOKUP(A9255, BMI!A:A, BMI!E:E, "Missing", 0) -> 36.1 | H9255: =_xlfn.XLOOKUP(A9255, Cholesterol!A:A, Cholesterol!E:E, "Missing", 0) -> 163

Sheet BMI
A1: SEQN | B1: BMI | C1: CHECK_BLANK | D1: =MEDIAN(B:B) -> 25.8 | E1: BMI_CLEANED
A2: 93703 | B2: 17.5 | C2: =IF(B2="","Blank","OK") -> OK | E2: =IF(B2="", $D$1, B2) -> 17.5
A3: 93704 | B3: 15.7 | C3: =IF(B3="","Blank","OK") -> OK | E3: =IF(B3="", $D$1, B3) -> 15.7
A4: 93705 | B4: 31.7 | C4: =IF(B4="","Blank","OK") -> OK | E4: =IF(B4="", $D$1, B4) -> 31.7
A5: 93706 | B5: 21.5 | C5: =IF(B5="","Blank","OK") -> OK | E5: =IF(B5="", $D$1, B5) -> 21.5
A6: 93707 | B6: 18.1 | C6: =IF(B6="","Blank","OK") -> OK | E6: =IF(B6="", $D$1, B6) -> 18.1
A7: 93708 | B7: 23.7 | C7: =IF(B7="","Blank","OK") -> OK | E7: =IF(B7="", $D$1, B7) -> 23.7
A8: 93709 | B8: 38.9 | C8: =IF(B8="","Blank","OK") -> OK | E8: =IF(B8="", $D$1, B8) -> 38.9
A9: 93710 | C9: =IF(B9="","Blank","OK") -> Blank | E9: =IF(B9="", $D$1, B9) -> 25.8
A10: 93711 | B10: 21.3 | C10: =IF(B10="","Blank","OK") -> OK | E10: =IF(B10="", $D$1, B10) -> 21.3
A11: 93712 | B11: 19.7 | C11: =IF(B11="","Blank","OK") -> OK | E11: =IF(B11="", $D$1, B11) -> 19.7
A12: 93713 | B12: 23.5 | C12: =IF(B12="","Blank","OK") -> OK | E12: =IF(B12="", $D$1, B12) -> 23.5
A13: 93714 | B13: 39.9 | C13: =IF(B13="","Blank","OK") -> OK | E13: =IF(B13="", $D$1, B13) -> 39.9
A14: 93715 | B14: 22.5 | C14: =IF(B14="","Blank","OK") -> OK | E14: =IF(B14="", $D$1, B14) -> 22.5
A15: 93716 | B15: 30.7 | C15: =IF(B15="","Blank","OK") -> OK | E15: =IF(B15="", $D$1, B15) -> 30.7
A16: 93717 | B16: 24.5 | C16: =IF(B16="","Blank","OK") -> OK | E16: =IF(B16="", $D$1, B16) -> 24.5
A17: 93718 | B17: 22 | C17: =IF(B17="","Blank","OK") -> OK | E17: =IF(B17="", $D$1, B17) -> 22
A18: 93719 | B18: 26 | C18: =IF(B18="","Blank","OK") -> OK | E18: =IF(B18="", $D$1, B18) -> 26
A19: 93720 | C19: =IF(B19="","Blank","OK") -> Blank | E19: =IF(B19="", $D$1, B19) -> 25.8
A20: 93721 | B20: 35.9 | C20: =IF(B20="","Blank","OK") -> OK | E20: =IF(B20="", $D$1, B20) -> 35.9
A21: 93722 | B21: 23.8 | C21: =IF(B21="","Blank","OK") -> OK | E21: =IF(B21="", $D$1, B21) -> 23.8
A22: 93723 | B22: 22.4 | C22: =IF(B22="","Blank","OK") -> OK | E22: =IF(B22="", $D$1, B22) -> 22.4
A23: 93724 | B23: 14.7 | C23: =IF(B23="","Blank","OK") -> OK | E23: =IF(B23="", $D$1, B23) -> 14.7
A24: 93725 | B24: 16.1 | C24: =IF(B24="","Blank","OK") -> OK | E24: =IF(B24="", $D$1, B24) -> 16.1
A25: 93726 | B25: 31.1 | C25: =IF(B25="","Blank","OK") -> OK | E25: =IF(B25="", $D$1, B25) -> 31.1
A26: 93727 | B26: 23.9 | C26: =IF(B26="","Blank","OK") -> OK | E26: =IF(B26="", $D$1, B26) -> 23.9
A27: 93728 | B27: 33.4 | C27: =IF(B27="","Blank","OK") -> OK | E27: =IF(B27="", $D$1, B27) -> 33.4
A28: 93729 | B28: 27.6 | C28: =IF(B28="","Blank","OK") -> OK | E28: =IF(B28="", $D$1, B28) -> 27.6
A29: 93730 | B29: 28.6 | C29: =IF(B29="","Blank","OK") -> OK | E29: =IF(B29="", $D$1, B29) -> 28.6
A30: 93731 | B30: 27.6 | C30: =IF(B30="","Blank","OK") -> OK | E30: =IF(B30="", $D$1, B30) -> 27.6
A31: 93732 | B31: 21.3 | C31: =IF(B31="","Blank","OK") -> OK | E31: =IF(B31="", $D$1, B31) -> 21.3
... A45: 93747 | B45: 22.1 | C45: =IF(B45="","Blank","OK") -> OK | E45: =IF(B45="", $D$1, B45) -> 22.1
A46: 93748 | C46: =IF(B46="","Blank","OK") -> Blank | E46: =IF(B46="", $D$1, B46) -> 25.8
A47: 93749 | C47: =IF(B47="","Blank","OK") -> Blank | E47: =IF(B47="", $D$1, B47) -> 25.8
A48: 93751 | B48: 25.2 | C48: =IF(B48="","Blank","OK") -> OK | E48: =IF(B48="", $D$1, B48) -> 25.2
A49: 93752 | B49: 25.5 | C49: =IF(B49="","Blank","OK") -> OK | E49: =IF(B49="", $D$1, B49) -> 25.5
A50: 93753 | B50: 24.6 | C50: =IF(B50="","Blank","OK") -> OK | E50: =IF(B50="", $D$1, B50) -> 24.6
A51: 93754 | B51: 33.4 | C51: =IF(B51="","Blank","OK") -> OK | E51: =IF(B51="", $D$1, B51) -> 33.4
A52: 93755 | B52: 29.4 | C52: =IF(B52="","Blank","OK") -> OK | E52: =IF(B52="", $D$1, B52) -> 29.4
A53: 93756 | B53: 29.2 | C53: =IF(B53="","Blank","OK") -> OK | E53: =IF(B53="", $D$1, B53) -> 29.2
...

Sheet Cholesterol
A1: SEQN | B1: TOTAL_CHOLESTEROL | C1: BLANK_CHECK | D1: =MEDIAN(B:B) -> 176 | E1: CHOLESTERO_CLEANED
A2: 93705 | B2: 157 | C2: =IF(B2="","Blank","OK") -> OK | E2: =IF(B2="", $D$1, B2) -> 157
A3: 93706 | B3: 148 | C3: =IF(B3="","Blank","OK") -> OK | E3: =IF(B3="", $D$1, B3) -> 148
A4: 93707 | B4: 189 | C4: =IF(B4="","Blank","OK") -> OK | E4: =IF(B4="", $D$1, B4) -> 189
A5: 93708 | B5: 209 | C5: =IF(B5="","Blank","OK") -> OK | E5: =IF(B5="", $D$1, B5) -> 209
A6: 93709 | B6: 176 | C6: =IF(B6="","Blank","OK") -> OK | E6: =IF(B6="", $D$1, B6) -> 176
A7: 93711 | B7: 238 | C7: =IF(B7="","Blank","OK") -> OK | E7: =IF(B7="", $D$1, B7) -> 238
A8: 93712 | B8: 182 | C8: =IF(B8="","Blank","OK") -> OK | E8: =IF(B8="", $D$1, B8) -> 182
A9: 93713 | B9: 184 | C9: =IF(B9="","Blank","OK") -> OK | E9: =IF(B9="", $D$1, B9) -> 184
A10: 93714 | B10: 230 | C10: =IF(B10="","Blank","OK") -> OK | E10: =IF(B10="", $D$1, B10) -> 230
A11: 93715 | B11: 180 | C11: =IF(B11="","Blank","OK") -> OK | E11: =IF(B11="", $D$1, B11) -> 180
A12: 93716 | B12: 225 | C12: =IF(B12="","Blank","OK") -> OK | E12: =IF(B12="", $D$1, B12) -> 225
A13: 93717 | B13: 213 | C13: =IF(B13="","Blank","OK") -> OK | E13: =IF(B13="", $D$1, B13) -> 213
... A18: 93723 | B18: 202 | C18: =IF(B18="","Blank","OK") -> OK | E18: =IF(B18="", $D$1, B18) -> 202
A19: 93725 | C19: =IF(B19="","Blank","OK") -> Blank | E19: =IF(B19="", $D$1, B19) -> 176
A20: 93726 | B20: 176 | C20: =IF(B20="","Blank","OK") -> OK | E20: =IF(B20="", $D$1, B20) -> 176
A21: 93727 | B21: 167 | C21: =IF(B21="","Blank","OK") -> OK | E21: =IF(B21="", $D$1, B21) -> 167
A22: 93728 | B22: 143 | C22: =IF(B22="","Blank","OK") -> OK | E22: =IF(B22="", $D$1, B22) -> 143
A23: 93729 | B23: 165 | C23: =IF(B23="","Blank","OK") -> OK | E23: =IF(B23="", $D$1, B23) -> 165
A24: 93730 | B24: 221 | C24: =IF(B24="","Blank","OK") -> OK | E24: =IF(B24="", $D$1, B24) -> 221
A25: 93731 | B25: 153 | C25: =IF(B25="","Blank","OK") -> OK | E25: =IF(B25="", $D$1, B25) -> 153
A26: 93732 | C26: =IF(B26="","Blank","OK") -> Blank | E26: =IF(B26="", $D$1, B26) -> 176
A27: 93733 | B27: 153 | C27: =IF(B27="","Blank","OK") -> OK | E27: =IF(B27="", $D$1, B27) -> 153
A28: 93735 | B28: 121 | C28: =IF(B28="","Blank","OK") -> OK | E28: =IF(B28="", $D$1, B28) -> 121
A29: 93736 | B29: 161 | C29: =IF(B29="","Blank","OK") -> OK | E29: =IF(B29="", $D$1, B29) -> 161
A30: 93737 | B30: 171 | C30: =IF(B30="","Blank","OK") -> OK | E30: =IF(B30="", $D$1, B30) -> 171
A31: 93738 | B31: 146 | C31: =IF(B31="","Blank","OK") -> OK | E31: =IF(B31="", $D$1, B31) -> 146
A32: 93740 | C32: =IF(B32="","Blank","OK") -> Blank | E32: =IF(B32="", $D$1, B32) -> 176
A33: 93741 | B33: 198 | C33: =IF(B33="","Blank","OK") -> OK | E33: =IF(B33="", $D$1, B33) -> 198
A34: 93742 | B34: 160 | C34: =IF(B34="","Blank","OK") -> OK | E34: =IF(B34="", $D$1, B34) -> 160
A35: 93743 | B35: 146 | C35: =IF(B35="","Blank","OK") -> OK | E35: =IF(B35="", $D$1, B35) -> 146
A36: 93744 | B36: 160 | C36: =IF(B36="","Blank","OK") -> OK | E36: =IF(B36="", $D$1, B36) -> 160
A37: 93746 | B37: 175 | C37: =IF(B37="","Blank","OK") -> OK | E37: =IF(B37="", $D$1, B37) -> 175
A38: 93747 | B38: 146 | C38: =IF(B38="","Blank","OK") -> OK | E38: =IF(B38="", $D$1, B38) -> 146
A39: 93751 | B39: 125 | C39: =IF(B39="","Blank","OK") -> OK | E39: =IF(B39="", $D$1, B39) -> 125
A40: 93752 | B40: 262 | C40: =IF(B40="","Blank","OK") -> OK | E40: =IF(B40="", $D$1, B40) -> 262
A41: 93753 | C41: =IF(B41="","Blank","OK") -> Blank | E41: =IF(B41="", $D$1, B41) -> 176
A42: 93754 | B42: 135 | C42: =IF(B42="","Blank","OK") -> OK | E42: =IF(B42="", $D$1, B42) -> 135
A43: 93755 | B43: 182 | C43: =IF(B43="","Blank","OK") -> OK | E43: =IF(B43="", $D$1, B43) -> 182
A44: 93756 | B44: 241 | C44: =IF(B44="","Blank","OK") -> OK | E44: =IF(B44="", $D$1, B44) -> 241
...

Sheet Master_data
A1: SEQN | B1: GENDER_LABEL | C1: AGE_CLEANED | D1: BMI_CLEANDED | E1: CHOLESTEROL_CLEANED
A2: 93703 | B2: Female | C2: 2 | D2: =_xlfn.XLOOKUP(A2, BMI!A:A, BMI!E:E, "Missing", 0) -> 17.5 | E2: =_xlfn.XLOOKUP(A2, Cholesterol!A:A, Cholesterol!E:E, "Missing", 0) -> Missing
A3: 93704 | B3: Male | C3: 2 | D3: =_xlfn.XLOOKUP(A3, BMI!A:A, BMI!E:E, "Missing", 0) -> 15.7 | E3: =_xlfn.XLOOKUP(A3, Cholesterol!A:A, Cholesterol!E:E, "Missing", 0) -> Missing
A4: 93705 | B4: Female | C4: 66 | D4: =_xlfn.XLOOKUP(A4, BMI!A:A, BMI!E:E, "Missing", 0) -> 31.7 | E4: =_xlfn.XLOOKUP(A4, Cholesterol!A:A, Cholesterol!E:E, "Missing", 0) -> 157
A5: 93706 | B5: Male | C5: 18 | D5: =_xlfn.XLOOKUP(A5, BMI!A:A, BMI!E:E, "Missing", 0) -> 21.5 | E5: =_xlfn.XLOOKUP(A5, Cholesterol!A:A, Cholesterol!E:E, "Missing", 0) -> 148
A6: 93707 | B6: Male | C6: 13 | D6: =_xlfn.XLOOKUP(A6, BMI!A:A, BMI!E:E, "Missing", 0) -> 18.1 | E6: =_xlfn.XLOOKUP(A6, Cholesterol!A:A, Cholesterol!E:E, "Missing", 0) -> 189
A7: 93708 | B7: Female | C7: 66 | D7: =_xlfn.XLOOKUP(A7, BMI!A:A, BMI!E:E, "Missing", 0) -> 23.7 | E7: =_xlfn.XLOOKUP(A7, Cholesterol!A:A, Cholesterol!E:E, "Missing", 0) -> 209
A8: 93709 | B8: Female | C8: 75 | D8: =_xlfn.XLOOKUP(A8, BMI!A:A, BMI!E:E, "Missing", 0) -> 38.9 | E8: =_xlfn.XLOOKUP(A8, Cholesterol!A:A, Cholesterol!E:E, "Missing", 0) -> 176
A9: 93710 | B9: Female | C9: 31 | D9: =_xlfn.XLOOKUP(A9, BMI!A:A, BMI!E:E, "Missing", 0) -> 25.8 | E9: =_xlfn.XLOOKUP(A9, Cholesterol!A:A, Cholesterol!E:E, "Missing", 0) -> Missing
A10: 93711 | B10: Male | C10: 56 | D10: =_xlfn.XLOOKUP(A10, BMI!A:A, BMI!E:E, "Missing", 0) -> 21.3 | E10: =_xlfn.XLOOKUP(A10, Cholesterol!A:A, Cholesterol!E:E, "Missing", 0) -> 238
A11: 93712 | B11: Male | C11: 18 | D11: =_xlfn.XLOOKUP(A11, BMI!A:A, BMI!E:E, "Missing", 0) -> 19.7 | E11: =_xlfn.XLOOKUP(A11, Cholesterol!A:A, Cholesterol!E:E, "Missing", 0) -> 182
A12: 93713 | B12: Male | C12: 67 | D12: =_xlfn.XLOOKUP(A12, BMI!A:A, BMI!E:E, "Missing", 0) -> 23.5 | E12: =_xlfn.XLOOKUP(A12, Cholesterol!A:A, Cholesterol!E:E, "Missing", 0) -> 184
A13: 93714 | B13: Female | C13: 54 | D13: =_xlfn.XLOOKUP(A13, BMI!A:A, BMI!E:E, "Missing", 0) -> 39.9 | E13: =_xlfn.XLOOKUP(A13, Cholesterol!A:A, Cholesterol!E:E, "Missing", 0) -> 230
... A9255: 102956 | B9255: Male | C9255: 38 | D9255: =_xlfn.XLOOKUP(A9255, BMI!A:A, BMI!E:E, "Missing", 0) -> 36.1 | E9255: =_xlfn.XLOOKUP(A9255, Cholesterol!A:A, Cholesterol!E:E, "Missing", 0) -> 163

Sheet BMI_Analysis
A3: GENDER_LABEL | B3: Average of BMI_CLEANDED
A4: Female | B4: 26.891334
A5: Male | B5: 26.124877
A6: Grand Total | B6: 26.515062

Sheet Detail1
A1: Details for Average of CHOLESTEROL_CLEANED - GENDER_LABEL: Male
A3: SEQN | B3: GENDER_LABEL | C3: AGE_CLEANED | D3: BMI_CLEANDED | E3: CHOLESTEROL_CLEANED
A4: 102956 | B4: Male | C4: 38 | D4: 36.1 | E4: 163
A5: 93704 | B5: Male | C5: 2 | D5: 15.7 | E5: Missing
A6: 102953 | B6: Male | C6: 42 | D6: 35.8 | E6: 182
A7: 93706 | B7: Male | C7: 18 | D7: 21.5 | E7: 148
A8: 93707 | B8: Male | C8: 13 | D8: 18.1 | E8: 189
A9: 102951 | B9: Male | C9: 4 | D9: 20.1 | E9: Missing
A10: 102950 | B10: Male | C10: 64 | D10: Missing | E10: Missing
A11: 102949 | B11: Male | C11: 33 | D11: 23.7 | E11: 201
A12: 93711 | B12: Male | C12: 56 | D12: 21.3 | E12: 238
A13: 93712 | B13: Male | C13: 18 | D13: 19.7 | E13: 182
A14: 93713 | B14: Male | C14: 67 | D14: 23.5 | E14: 184
A15: 102947 | B15: Male | C15: 75 | D15: 25.2 | E15: 143
A16: 93715 | B16: Male | C16: 71 | D16: 22.5 | E16: 180
A17: 93716 | B17: Male | C17: 61 | D17: 30.7 | E17: 225
A18: 93717 | B18: Male | C18: 22 | D18: 24.5 | E18: 213
A19: 93718 | B19: Male | C19: 45 | D19: 22 | E19: 152
A20: 102946 | B20: Male | C20: 65 | D20: 30.4 | E20: 214
A21: 102945 | B21: Male | C21: 15 | D21: 22.1 | E21: 116
A22: 102944 | B22: Male | C22: 55 | D22: 29.6 | E22: 214
A23: 102936 | B23: Male | C23: 1 | D23: 25.8 | E23: Missing
A24: 93723 | B24: Male | C24: 64 | D24: 22.4 | E24: 202
A25: 102934 | B25: Male | C25: 48 | D25: 26.3 | E25: 180
A26: 102929 | B26: Male | C26: 60 | D26: 34.8 | E26: 192
A27: 102928 | B27: Male | C27: 31 | D27: Missing | E27: Missing
A28: 93727 | B28: Male | C28: 70 | D28: 23.9 | E28: 167
A29: 93728 | B29: Male | C29: 53 | D29: 33.4 | E29: 143
A30: 93729 | B30: Male | C30: 42 | D30: 27.6 | E30: 165
A31: 93730 | B31: Male | C31: 57 | D31: 28.6 | E31: 221
A32: 93731 | B32: Male | C32: 20 | D32: 27.6 | E32: 153
A33: 93732 | B33: Male | C33: 72 | D33: 21.3 | E33: 176
A34: 102927 | B34: Male | C34: 31 | D34: 25.8 | E34: Missing
A35: 93734 | B35: Male | C35: 13 | D35: Missing | E35: Missing
A36: 93735 | B36: Male | C36: 52 | D36: 35.1 | E36: 121
A37: 93736 | B37: Male | C37: 11 | D37: 17.9 | E37: 161
A38: 93737 | B38: Male | C38: 8 | D38: 18.5 | E38: 171
A39: 93738 | B39: Male | C39: 26 | D39: 33.7 | E39: 146
A40: 102925 | B40: Male | C40: 3 | D40: 15.7 | E40: Missing
A41: 93740 | B41: Male | C41: 72 | D41: 30.6 | E41: 176
...

Sheet Cholesterol_Analysis
A3: GENDER_LABEL | B3: Average of CHOLESTEROL_CLEANED
A4: Female | B4: 182.30656
A5: Male | B5: 176.61076
A6: Grand Total | B6: 179.52952

Sheet Combined_Analysis
A3: GENDER_LABEL | B3: Average of BMI_CLEANDED | C3: Average of CHOLESTEROL_CLEANED
A4: Female | B4: 26.891334 | C4: 182.30656
A5: Male | B5: 26.124877 | C5: 176.61076
A6: Grand Total | B6: 26.515062 | C6: 179.52952

Sheet Dashboard
K9: GENDER_LABEL | L9: Average of BMI_CLEANDED | M9: Average of CHOLESTEROL_CLEANED
K10: Female | L10: 26.891334 | M10: 182.30656
K11: Male | L11: 26.124877 | M11: 176.61076
K12: Grand Total | L12: 26.515062 | M12: 179.52952
